200
200
200
200
200
200
200
200
200
200
200
200
200
200
200
200
200
200
200
200
200
200
200
200
200
200
200
200
200
200
200
200
200
200
200
200
200
200
200
200
200
200
200
200
200
200
200
200
200
200
200
200
200
200
200
200
200
200
Traceback (most recent call last):
  File "get_pmid.py", line 76, in <module>
    curs.execute(query)
  File "/home/hogking/.pyenv/versions/3.6.0/lib/python3.6/site-packages/pymysql/cursors.py", line 166, in execute
    result = self._query(query)
  File "/home/hogking/.pyenv/versions/3.6.0/lib/python3.6/site-packages/pymysql/cursors.py", line 322, in _query
    conn.query(q)
  File "/home/hogking/.pyenv/versions/3.6.0/lib/python3.6/site-packages/pymysql/connections.py", line 856, in query
    self._affected_rows = self._read_query_result(unbuffered=unbuffered)
  File "/home/hogking/.pyenv/versions/3.6.0/lib/python3.6/site-packages/pymysql/connections.py", line 1057, in _read_query_result
    result.read()
  File "/home/hogking/.pyenv/versions/3.6.0/lib/python3.6/site-packages/pymysql/connections.py", line 1340, in read
    first_packet = self.connection._read_packet()
  File "/home/hogking/.pyenv/versions/3.6.0/lib/python3.6/site-packages/pymysql/connections.py", line 987, in _read_packet
    packet_header = self._read_bytes(4)
  File "/home/hogking/.pyenv/versions/3.6.0/lib/python3.6/site-packages/pymysql/connections.py", line 1033, in _read_bytes
    CR.CR_SERVER_LOST, "Lost connection to MySQL server during query")
pymysql.err.OperationalError: (2013, 'Lost connection to MySQL server during query')
